Workbook

Sheet Income Statement
B2: 3 Year Income Statement
B3: (in Mn Pounds) | C3: 2026E | D3: 2027E | E3: 2028E | F3: Notes
B4: Revenue
B5: Licensing & Subscription | C5: =C36 -> 0 | D5: =D36 -> 0 | E5: =E36 -> 0
B6: Managed Services | C6: =C39 -> 0 | D6: =D39 -> 0 | E6: =E39 -> 0
B7: Total Revenue | C7: =SUM(C5:C6) -> 0 | D7: =SUM(D5:D6) -> 0 | E7: =SUM(E5:E6) -> 0
B9: Cost of Sales
B10: Cost of Licensing & Subscription | C10: =C46*C34 -> 12816 | D10: =D46*D34 -> 0 | E10: =E46*E34 -> 0
B11: Cost of Managed Services | C11: =C50*C34 -> 460000 | D11: =D50 -> 0 | E11: =E50 -> 0
B12: Cost of Sales | C12: =SUM(C10:C11) -> 472816 | D12: =SUM(D10:D11) -> 0 | E12: =SUM(E10:E11) -> 0
B14: Gross Profit | C14: =C7+C12 -> 472816 | D14: =D7+D12 -> 0 | E14: =E7+E12 -> 0
B16: Operating Costs
B17: Sales & Marketing | C17: =C58 -> 0 | D17: =D58 -> 0 | E17: =E58 -> 0
B18: Research & Development | C18: =C72 -> 0 | D18: =D72 -> 0 | E18: =E72 -> 0
B19: General & Admin | C19: =C67 -> 0 | D19: =D67 -> 0 | E19: =E67 -> 0
B20: EBITDA | C20: =C14+SUM(C17:C19) -> 472816 | D20: =D14+SUM(D17:D19) -> 0 | E20: =E14+SUM(E17:E19) -> 0
B21: D&A
B22: Operating Profit (EBIT) | C22: =C20+C21 -> 472816 | D22: =D20+D21 -> 0 | E22: =E20+E21 -> 0
B24: Interest
B25: Other Income/Expense (Grants, etc.)
B26: Profit Before Tax | C26: =C22+SUM(C24:C25) -> 472816 | D26: =D22+SUM(D24:D25) -> 0 | E26: =E22+SUM(E24:E25) -> 0
B27: Taxes
B28: PAT/Net Income | C28: =C26+C27 -> 472816 | D28: =D26+D27 -> 0 | E28: =E26+E27 -> 0
B31: Income Statement Drivers & Assumptions
B32: (in Mn Pounds) | C32: 2026E | D32: 2027E | E32: 2028E | F32: Notes
B33: Revenue Assumptions
B34: Number of SMEs Acquired | C34: 50 | D34: 100 | E34: 150
B35: Pricing
B36: Revenue from Licensing/Subscription | C36: =C34*C35 -> 0 | D36: =D34*D35 -> 0 | E36: =E34*E35 -> 0
B38: Managed Service Fee
B39: Revenue from Managed Services | C39: =C38*C34 -> 0 | D39: =D38*D34 -> 0 | E39: =E38*E34 -> 0
B41: Cost of Sales Assumptions (Per Customer)
B42: Cloud & Infrastructure Costs | C42: ='Cost of Sales Drivers'!D20 -> 244.8
B43: Paid APIs (LLMs) | C43: ='Cost of Sales Drivers'!D9*12 -> 11.52
B44: Databases, feature stores, servicing platforms | C44: ='Cost of Sales Drivers'!B44 -> 0
B45: API Licensing Costs | C45: =SUM(C43:C44) -> 11.52 | D45: =SUM(D43:D44) -> 0 | E45: =SUM(E43:E44) -> 0
B46: Cost of Licensing/Subscription | C46: =C42+C45 -> 256.32 | D46: =D42+D45 -> 0 | E46: =E42+E45 -> 0
B48: People Cost | C48: ='Cost of Sales Drivers'!D54 -> 8200
B49: Tools/Infra Cost for Managed Services | C49: ='Cost of Sales Drivers'!B60 -> 1000
B50: Cost of Managed Services | C50: =C48+C49 -> 9200 | D50: =D48+D49 -> 0 | E50: =E48+E49 -> 0
...

Sheet Employee Costs
A2: Team Structure & Employee Cost
A4: Role | B4: Headcount | C4: Salary | D4: Salary Assumption | E4: Responsibility
A5: CEO/Co-Founder | B5: 1 | C5: £0-20K | E5: Sales, strategy, Fundraising
A6: COO/Co-Founder | B6: 1 | C6: £0-20K | E6: Operations, Energy SME, Fundraising
A7: CTO/Lead Engineer | B7: 1 | C7: £90K | E7: Product development, architecture
A8: Backend Engineer | B8: 1 | C8: £70K | E8: Core engineering
A9: ML/AI Engineer | B9: 0.5 | C9: £50K | E9: LLM fine-tuning (contract/part-time)
A10: Growth/Marketing Person | B10: 1 | C10: £45K | E10: Content, analytics, customer success (ONE person does it all)
A11: Part-Time Finance/Ops | B11: 0.3 | C11: £20K | E11: Accounting, compliance
A12: TOTAL | B12: 5.3 FTE | C12: £275K | E12: —

Sheet Cost of Sales Drivers
A2: Infrastructure Cost
A4: LLM API Licensing (GPT-5 Fine-Tuned)
A5: Cost Component | B5: Rate | C5: Per Query (Energy Analysis) | D5: Monthly Per Customer | E5: Sources
A6: Input Tokens | B6: $0.625 per 1M tokens | C6: 0.00125 | D6: £0.60 | E6: https://platform.openai.com/docs/pricing
A7: Output Tokens | B7: $5.00 per 1M tokens | C7: 0.0025 | D7: £0.36
A8: Fine-Tuning (Training) | B8: $25 per 1M tokens | C8: One-time | D8: —
A9: Total Per Query | B9: — | C9: 0.003 | D9: 0.96
A11: Cloud & Infrastructure Costs (Multi-Tenant AWS)
A12: Cost Item | B12: Monthly Per 5-Customer Group | C12: Per Customer/Month | D12: Annual Per Customer | E12: Sources
A13: Compute (EC2) | B13: £40 | C13: £8 | D13: £96 | E13: 1. https://aws.amazon.com/blogs/apn/calculating-tenant-costs-in-saas-environments/ 2. https://www.cloudzero.com/blog/saas-gross-margin-benchmarks/
A14: Database (Aurora PostgreSQL) | B14: £25 | C14: £5 | D14: £60
A15: Storage & CDN | B15: £8 | C15: £1.60 | D15: £19.20
A16: Monitoring & Logging | B16: £4 | C16: £0.80 | D16: £9.60
A17: Data Transfer | B17: £4 | C17: £0.80 | D17: £9.60
A18: Security & Compliance | B18: £8 | C18: £1.60 | D18: £19.20
A19: Backup & DR | B19: £13 | C19: £2.60 | D19: £31.20
A20: TOTAL | B20: 102 | C20: 20.4 | D20: 244.8
A22: Additional Datasets for Model Training
A23: Data Source | B23: Cost | C23: What You Get | E23: URL
A24: UK Elexon Grid Data | B24: FREE | C24: Real-time + historical UK electricity pricing, demand, generation (5-min intervals, 5+ years) | E24: https://adgefficiency.com/blog/elexon-api-uk-electricity-grid-data-with-python/
A25: Energy Dashboard UK | B25: FREE | C25: Real-time grid carbon intensity, generation mix, renewable %), updated 5-30 mins | E25: https://www.energydashboard.co.uk/live
A26: UK Power Networks OpenData | B26: FREE | C26: Network topology, 1,000 generation sites, capacity data, renewable connections | E26: https://www.ukpowernetworks.co.uk/our-company/open-data-portal
A27: EIA CBECS (US) | B27: FREE | C27: 5.6M commercial building benchmarks, consumption by end-use, heating/cooling/lighting breakdowns | E27: https://www.eia.gov/consumption/commercial/
A28: Electricity Costs API | B28: FREE | C28: GB regional electricity costs (p/kWh), commodity + network charges, by DNO region | E28: https://electricitycosts.org.uk/api/
A29: Open-Power-System-Data | B29: FREE | C29: European grid loading, wind/solar production, prices, capacity data (CSV, commercial use ok) | E29: https://data.open-power-system-data.org/
A30: IEA Wind SCADA | B30: FREE | C30: 4+ years real wind farm SCADA (10-min intervals), equipment performance patterns | E30: https://iea-wind.org/task43/task-43-open-data/
A31: Modo Energy API | B31: FREE | C31: California ISO market data (LMPs, battery dispatch, ancillary services) – learning reference | E31: https://modoenergy.com/research/en/free-energy-market-data
A32: Public Datasets (Kaggle) | B32: FREE | C32: General building energy cost datasets, residential + commercial patterns | E32: https://www.kaggle.com/datasets/andreylss/residential-and-commercial-energy-cost-dataset
A33: UC Berkeley Building Dataset | B33: FREE | C33: 3-year office building operational data (6-min intervals, end-use metering) | E33: https://openenergyhub.ornl.gov/
A34: Data Source | B34: Cost | C34: What You Get | E34: URL | F34: Best For
A35: Cogent DataHub License | B35: £2,500-5,000/year | C35: Industrial SCADA data collection platform (Modbus, OPC-UA, BACnet support) | E35: https://cogentdatahub.com/purchasing/ | F35: Connecting to 50-100 customer buildingscogentdatahub​
A36: EnergyID Premium | B36: £1,200-2,400/year | C36: EU building energy data, peer benchmarking, half-hourly metering (10-20 buildings) | E36: https://www.energyid.eu/en/pricing/ | F36: European market expansionenergyid​
A37: Facilities Mgmt Partnership | B37: £500-5,000/year | C37: Access to 50-200 buildings (Mitie, Arcus, Engie properties) | E37: Partner agreements | F37: Real SME/commercial consumption dataintegrate+1​
A38: Synthetic Data Generation | B38: £5,000-10,000/year | C38: Fill gaps in real data via AI-generated building consumption profiles | E38: Custom vendors | F38: Scale training data 10xbigdasolutions​
A39: Bloomberg New Energy Finance | B39: £25,000-50,000/year | C39: Global renewable pricing trends, battery cost data, market forecasts | F39: Market context (not real-time ops)wallstreetprep+1​
A40: Yes Energy/PowerSignals | B40: £10,000+/year | C40: Ontario (IESO) market data, demand forecasts, nodal pricing | F40: If expanding to Canadayesenergy​
A41: CAISO Historical Data | B41: Custom | C41: Advanced grid pricing, congestion patterns | F41: If entering California marketcaiso​
A43: Dataset Pricing | B43: Annual Cost (Pounds) | C43: Coverage | D43: Sources
A44: MVP/Free Tier | B44: 0 | C44: UK building benchmarks + grid data | D44: 8+ free sourceselectricitycosts+6​
A45: Growth Tier | B45: 3500 | C45: Real SME data partnerships + commercial tools | D45: Cogent DataHub + facility partnershipsintegrate+1​
...

Sheet Balance Sheet
B2: 3 Year Balance Sheet
B3: (in Mn Pounds) | C3: 2026E | D3: 2027E | E3: 2028E | F3: Notes
B4: Assets
B5: Cash & Cash Equivalents | C5: ='Cashflow Statement'!C29 -> 472816 | D5: ='Cashflow Statement'!D29 -> 472816 | E5: ='Cashflow Statement'!E29 -> 472816
B6: Accounts Receivable | C6: =C43 -> 0 | D6: =D43 -> 0 | E6: =E43 -> 0
B7: Prepaid Expenses | F7: Are there any prepayments to be made?
B8: R&D Tax Credit Receivable | F8: UK SME Scheme cash inflow
B9: Current Assets | C9: =SUM(C5:C8) -> 472816 | D9: =SUM(D5:D8) -> 472816 | E9: =SUM(E5:E8) -> 472816
B11: Property,Plant & Equipments (PP&E) | C11: =C51 -> 0 | D11: =D51 -> 0 | E11: =E51 -> 0 | F11: Laptops, Servers, etc.
B12: Intangible Assets | C12: =C47 -> 0 | D12: =D47 -> 0 | E12: =E47 -> 0 | F12: Patents if Any
B13: Non-Current Assets | C13: =SUM(C11:C12) -> 0 | D13: =SUM(D11:D12) -> 0 | E13: =SUM(E11:E12) -> 0
B14: Total Assets | C14: =C13+C9 -> 472816 | D14: =D13+D9 -> 472816 | E14: =E13+E9 -> 472816
B16: Liabilities
B17: Short Term Debt | F17: If Debt is to be taken
B18: Accounts Payable
B19: Accrued Expenses | F19: Salaries or Cloud & Infra Bills
B20: Deferred Revenue | F20: Customer Pre-payments
B21: Current Liabilities | C21: =SUM(C17:C20) -> 0 | D21: =SUM(D17:D20) -> 0 | E21: =SUM(E17:E20) -> 0
B23: Long Term Debt | F23: If Debt is to be taken
B24: Long Term Deferred Revenue | F24: Multi Year Contracts
B25: Lease Liabilities | F25: If Office Space is leased
B26: Non-Current Liabilites | C26: =SUM(C23:C25) -> 0 | D26: =SUM(D23:D25) -> 0 | E26: =SUM(E23:E25) -> 0
B27: Total Liabilities | C27: =C21+C26 -> 0 | D27: =D21+D26 -> 0 | E27: =E21+E26 -> 0
B29: Equity
B30: Share Capital | F30: Any funding Inflows
B31: Share Premium | F31: Funds above Par Value
B32: BOP | C32: 0 | D32: =C34 -> 472816 | E32: =D34 -> 472816
B33: Net Income | C33: ='Income Statement'!C28 -> 472816 | D33: ='Income Statement'!D28 -> 0 | E33: ='Income Statement'!E28 -> 0
B34: Retained Earnings | C34: =SUM(C32:C33) -> 472816 | D34: =SUM(D32:D33) -> 472816 | E34: =SUM(E32:E33) -> 472816
B35: Total Equity | C35: =C30+C31+C33 -> 472816 | D35: =D30+D31+D33 -> 0 | E35: =E30+E31+E33 -> 0
B38: Balance Sheet Drivers & Assumptions
B39: (in Mn Pounds) | C39: 2026E | D39: 2027E | E39: 2028E | F39: Notes
B41: Assets
B42: DSO (Days) | F42: Assume based on Payment Days
B43: Accounts Receivables | C43: ='Income Statement'!C7*(C42/265) -> 0 | D43: ='Income Statement'!D7*(D42/265) -> 0 | E43: ='Income Statement'!E7*(E42/265) -> 0
B45: Patents Value | F45: If any Patents
B46: Accumulated Amortization
B47: Net Intangibles | C47: =C45-C46 -> 0 | D47: =D45-D46 -> 0 | E47: =E45-E46 -> 0
B49: Cost of Laptops, Servers
B50: Accumulated Depreciation
...

Sheet Cashflow Statement
B2: 3 Year Cashflow Statement
B3: (in Mn Pounds) | C3: 2026E | D3: 2027E | E3: 2028E | F3: Notes
B4: Cash from Operating Activities
B5: Net Income | C5: ='Income Statement'!C28 -> 472816 | D5: ='Income Statement'!D28 -> 0 | E5: ='Income Statement'!E28 -> 0
B6: (+) D&A | C6: ='Income Statement'!C21 -> 0 | D6: ='Income Statement'!D21 -> 0 | E6: ='Income Statement'!E21 -> 0
B7: (+/-) Change in Accounts Receivable | C7: 0 | D7: =-('Balance Sheet'!D6-'Balance Sheet'!C6) -> 0 | E7: =-('Balance Sheet'!E6-'Balance Sheet'!D6) -> 0
B8: (+/-) Change in Prepaid Expenses | C8: 0 | D8: =-('Balance Sheet'!D7-'Balance Sheet'!C7) -> 0 | E8: =-('Balance Sheet'!E7-'Balance Sheet'!D7) -> 0
B9: (+/-) Change in Account Payable | C9: 0 | D9: ='Balance Sheet'!D18-'Balance Sheet'!C18 -> 0 | E9: ='Balance Sheet'!E18-'Balance Sheet'!D18 -> 0
B10: (+/-) Change in Accrued Expenses | C10: 0 | D10: ='Balance Sheet'!D19-'Balance Sheet'!C19 -> 0 | E10: ='Balance Sheet'!E19-'Balance Sheet'!D19 -> 0
B11: (+/-) Change in Deferred Expenses | C11: 0 | D11: ='Balance Sheet'!D20-'Balance Sheet'!C20 -> 0 | E11: ='Balance Sheet'!E20-'Balance Sheet'!D20 -> 0
B12: Net Cash from Operating Activities | C12: =SUM(C5:C11) -> 472816 | D12: =SUM(D5:D11) -> 0 | E12: =SUM(E5:E11) -> 0
B14: Cash from Investing Activities
B15: Purchase of PP&E | C15: ='Balance Sheet'!C49 -> 0 | D15: ='Balance Sheet'!D49 -> 0 | E15: ='Balance Sheet'!E49 -> 0
B16: Capital for Development of Intangibles | C16: ='Balance Sheet'!C45 -> 0 | D16: ='Balance Sheet'!D45 -> 0 | E16: ='Balance Sheet'!E45 -> 0
B17: Net Cash from Operating Activities | C17: =SUM(C15:C16) -> 0 | D17: =SUM(D15:D16) -> 0 | E17: =SUM(E15:E16) -> 0
B19: Cash from Financing Activities
B20: Proceeds from Equity Funding | F20: Based on Funding Info
B21: Proceeds from Grants (Non-Repayable)
B22: Proceeds from Borrowings
B23: Repayments of Borrowings/Lease
B24: Net Cash from Financing Activities | C24: =SUM(C20:C23) -> 0 | D24: =SUM(D20:D23) -> 0 | E24: =SUM(E20:E23) -> 0
B26: Increase/Decrease in Cash & Cash Equivalents | C26: =C12+C17+C24 -> 472816 | D26: =D12+D17+D24 -> 0 | E26: =E12+E17+E24 -> 0
B27: Beginning of Period Cash & Cash Equivalents | D27: =C29 -> 472816 | E27: =D29 -> 472816 | F27: Check Cash in Bank
B29: End of Period Cash & Cash Equivalents | C29: =C27+C26 -> 472816 | D29: =D27+D26 -> 472816 | E29: =E27+E26 -> 472816
